Workbook
Name Aplicaciones_Prevención_de_Heladas: Hoja1!$AT$2:$AT$3
Name Arriendos_Vehículos_Explotación: Hoja1!$S$2
Name Asesores_Legales: Hoja1!$AV$2
Name Asesoría_Contable: Hoja1!$AX$2
Name Asocianismo: Hoja1!$BW$3
Name Auditorias_y_Asesoría_Tributaria: Hoja1!$AW$2
Name Bacheos_Rutinarios_y_Otras_Actividades_Puntuales: Hoja1!$AL$2:$AL$6
Name Cafetería_Dispensador_de_Alimentos: Hoja1!$CF$3
Name Capacitación_y_Formación_del_Personal: Hoja1!$C$2:$C$3
Name Categorías: Hoja1!$C$2:$CF$2
Name Combustibles_y_Lubricantes_Vehículos_Explotación: Hoja1!$BK$3:$BK$4
Name Comunicaciones_Equipos_de_Radio: Hoja1!$BI$3
Name Comunicaciones_y_Enlace_de_Datos: Hoja1!$M$2:$M$4
Name Construcción_de_Elementos_de_Drenaje_Subsuperficial: Hoja1!$AE$2:$AE$5
Name Construcción_y_Mantenimiento_Elementos_de_Contención_Taludes: Hoja1!$AF$2:$AF$4
Name Control_de_Calidad: Hoja1!$CD$3
Name Correo: Hoja1!$N$2
Name Electricidad_e_Iluminación: Hoja1!$BH$3
Name Encuestas: Hoja1!$BA$2
Name Estacionamientos: Hoja1!$CA$3
Name Estudios_e_Inspecciones_Mayores_CyM: Hoja1!$BE$3
Name Estudios_e_Inspecciones_TC_CyM: Hoja1!$BD$3
Name Fotocopias: Hoja1!$K$2
Name Gastos_Comunes: Hoja1!$CE$3
Name Gastos_de_Viaje_Hoteles: Hoja1!$G$2
Name Gastos_de_Viaje_Otros: Hoja1!$H$2
Name Gastos_de_Viaje_Pasajes: Hoja1!$F$2
Name Gastos_Facturación_Medio_Pago_Electrónico: Hoja1!$BX$3
Name Gastos_Por_Eventos_Deportivos_y_Recreación: Hoja1!$E$2
Name Gestión_del_Tránsito_y_Apoyo_Accidentes: Hoja1!$AU$2:$AU$4
Name Honorarios: Hoja1!$CC$3
Name Impresión_Boletos: Hoja1!$I$2
Name Inst_Defensas_y_Otros_DC: Hoja1!$AJ$2:$AJ$6
Name Insumos_Licencias_e_Implementos_de_Computación_y_Software: Hoja1!$Y$2:$Y$4
Name Lista: 'Bienes&Servicios'!$I$12
Name Lista_Cat: Hoja1!$A$2:$A$53
Name Listado: Hoja1!$A$1:$A$53
Name M_R_MyR_de_Equipos_de_Emergenciade_Equipos_de_Emergencia: Hoja1!$BZ$3
Name Mantención_e_Insumos_de_Sistemas_de_CCTV: Hoja1!$W$2
Name Mantención_e_Insumos_Equipos_Túnel_y_Equipos_de_Emergencia: Hoja1!$X$2:$X$13
Name Mantención_e_Insumos_Postes_SOS_y_PMV: Hoja1!$V$2:$V$6
Name Mantención_e_Insumos_Sistema_de_Peajes: Hoja1!$T$2:$T$14
Name Mantención_Vehículos_Explotación: Hoja1!$Z$2
Name Mantención_y_Reparación_de_Instalaciones_ASG_Peajes_Paraderos: Hoja1!$U$2:$U$5
Name Mantención_y_Reparación_de_Luminarias: Hoja1!$AO$2:$AO$4
Name Mantención_y_Reparación_Pantallas_Acústicas: Hoja1!$AN$2:$AN$4
Name Mantención_y_Reposición_de_Señalización_Horizontal_y_Vertical: Hoja1!$AH$2:$AH$21
Name Mantenimiento_Calles_de_Servicio_Granulares: Hoja1!$AC$2:$AC$6
Name Mantenimiento_Mayor_En_Estructuras_y_Cauces: Hoja1!$AD$2:$AD$22
Name Mantenimiento_Pavimentos_de_Hormigón: Hoja1!$AB$2:$AB$7
Name Mantenimiento_Pavimentos_y_Bermas_de_Asfalto: Hoja1!$AA$2:$AA$37
Name MT2_Mantención_de_Pantallas_Acústicas: Hoja1!$AN$2:$AN$4
Name N°1_Capacitación_y_Formación_del_Personal: Hoja1!$C$2:$C$3
Name N°10_Útiles_de_Oficina: Hoja1!$L$2
Name N°11_Comunicaciones_y_Enlace_de_Datos: Hoja1!$M$2:$M$4
Name N°12_Correo: Hoja1!$N$2
Name N°13_Servicio_Transporte_de_Dinero: Hoja1!$O$2
Name N°14_Servicio_Legal_Notaría: Hoja1!$P$2
Name N°15_Servicio_de_Pesaje: Hoja1!$Q$2
Name N°16_Responsabilidad_Social_Empresarial_RSE: Hoja1!$R$2

Sheet Bienes
A1: EVALUACIÓN DEL DESEMPEÑO DE CONTRATISTAS Contrato de Suministro de Bienes
A3: NOMBRE DEL CONTRATISTA | G3: NIT
A4: NOMBRE DEL CONTACTO | G4: EMAIL
A6: 1. ETAPA DE EVALUACIÓN | I6: 2. FECHA DE EVALUACIÓN
A7: CONTRACTUAL | D7: FIN DEL CONTRATO | F7: POST CONTRACTUAL
A9: 3. INFORMACIÓN DEL CONTRATO
A10: NUMERO SAP | D10: FECHA INICIO | G10: FECHA FINAL
A11: VALOR COP | D11: VALOR USD | G11: VALOR EUR
A12: OBJETO
A15: 4. EVALUACIÓN DEL DESEMPEÑO
A16: CRITERIO A CUMPLIR | C16: DESCRIPCIÓN | G16: EVALUADOR | H16: CALIFICACIÓN (Puntos) | I16: DESEMPEÑO
A17: Calidad | B17: Calidad de los Bienes Suministrados: cumplimiento especificaciones | C17: Todos los bienes se recibieron a satisfacción y sin problemas de funcionamiento. | G17: ADMINISTRADOR DEL CONTRATO / RESPONSABLE TECNICO | I17: =+Datos!G50 -> 17.5
C18: Algunos de los bienes recibidos a satisfacción presentaron problemas de funcionamiento después de la entrega, pero fueron intervenidos oportunamente por el contratista.
C19: Algunos de los bienes recibidos a satisfacción presentaron problemas de funcionamiento después de la entrega, pero NO fueron intervenidos oportunamente por el contratista.
B20: Calidad de los Bienes Suministrados: cooperación | C20: El personal demuestra, sistemática y evidentemente cooperación que asegura el adecuado suministro de los bienes | G20: ADMINISTRADOR DEL CONTRATO / RESPONSABLE TECNICO | I20: =+Datos!G51 -> 17.5
C21: El personal demuestra poca o regular cooperación, lo que dificulta el adecuado suministro de los bienes
C22: El personal no demuestra cooperación, incluso cuando se le solicita, lo que dificulta el adecuado suministro de los bienes
A23: Oportunidad | B23: Oportunidad: cumplimiento de fechas /cantidades | C23: Todos los bienes fueron entregados en la(s) fecha(s) programada(s) inicialmente con el contratista. | G23: ADMINISTRADOR DEL CONTRATO / RESPONSABLE TECNICO | I23: =+Datos!G52 -> 35
C24: Algunos bienes NO fueron entregados en la(s) cantidad(es) y/o fecha(s) programada(s) con el contratista, pero se acordó una reprogramación.
C25: Los bienes NO fueron entregados en la(s) cantidad(es) y/o fecha(s) programada(s) con el contratista.
A26: Gestión | B26: Entrega de Documentos para Orden de Inicio. | C26: El tiempo de entrega a ISA de las Pólizas y demás documentos para dar la Orden de Inicio, fue menor o igual al tiempo establecido en el DSO. | G26: COMPRADOR | I26: =+Datos!G53 -> 15
C27: El tiempo de entrega a ISA de las Pólizas y demás documentos para dar la Orden de Inicio, fue mayor al tiempo establecido en el DSO.
B28: Entrega de Documentos Contractuales. | C28: Todas las facturas y sus soportes, la documentación contractual requerida durante la ejecución (informes, certificados, constancias, licencias, etc) y la documentación postcontractual (manuales, protocolos de pruebas, información técnica, etc) fueron entregadas de acuerdo a lo programado y sin errores. | G28: ADMINISTRADOR DEL CONTRATO / RESPONSABLE ADMINISTRATIVO | I28: =+Datos!G54 -> 15
C29: Algunas facturas y sus soportes, la documentación contractual requerida durante la ejecución (informes, certificados, constancias, licencias, etc) y/o la documentación postcontractual (manuales, protocolos de pruebas, información técnica, etc) fueron entregadas de acuerdo a lo programado pero con errores y como consecuencia se realizó su corrección.
C30: Algunas facturas y sus soportes, la documentación contractual requerida durante la ejecución (informes, certificados, constancias, licencias, etc) y/o la documentación postcontractual (manuales, protocolos de pruebas, información técnica, etc) NO fueron entregadas de acuerdo con lo programado y con errores.
A31: Código de ética / antifraude | B31: Código de ética / antifraude | C31: El contratista incurrió en faltas al código de ética / antifraude | G31: COMPRADOR / ADMINISTRADOR DEL CONTRATO/RESPONSABLE TÉCNICO / RESPONSABLE ADMINISTRATIVO
A33: 5. RESUMEN DE LA EVALUACIÓN | F33: 6. OBSERVACIONES GENERALES:
A34: CRITERIO | C34: CALIFICACIÓN POSIBLE | D34: CALIFICACIÓN OBTENIDA
A35: GESTIÓN | C35: 30 | D35: =+Datos!D58 -> 30
A36: CALIDAD | C36: 35 | D36: =+Datos!D59 -> 35
A37: OPORTUNIDAD | C37: 35 | D37: =+Datos!D60 -> 35
A38: EVALUACIÓN DE DESEMPEÑO | C38: 100 | D38: =SUM(D35:D37) -> 100
A40: VIOLACIÓN AL CÓDIGO DE ÉTICA / ANTIFRAUDE | C40: =+Datos!C55 -> FALSE
A41: TOTAL CALIFICACIÓN GENERAL | C41: 100 | D41: =IF(C40,0,D38) -> 100
A43: 7. RESPONSABLE TECNICO DEL CONTRATO | F43: 8. GERENTE o DIRECTOR DE AREA
A44: NOMBRE: | F44: NOMBRE:
A45: AREA: | F45: AREA:
A46: FIRMA: | F46: FIRMA:

Sheet Servicios
A1: EVALUACIÓN DEL DESEMPEÑO DE CONTRATISTAS Contrato de Prestación de Servicios
A3: NOMBRE DEL CONTRATISTA | G3: NIT | M3: GESTION | N3: CALIDAD | O3: OPORTUNIDAD
A4: NOMBRE DEL CONTACTO | G4: EMAIL | M4: GESTION | N4: CALIDAD | O4: OPORTUNIDAD
L5: CONDICIONADA | M5: 15 | N5: 15 | O5: 20
A6: 1. ETAPA DE EVALUACIÓN | I6: 2. FECHA DE EVALUACIÓN | L6: DEFICIENTE | M6: 0 | N6: 0 | O6: 0
A7: CONTRACTUAL | D7: FIN DEL CONTRATO | F7: POST CONTRACTUAL
L8: BUENA | M8: 25 | N8: 45 | O8: 30
L9: CONDICIONADA | M9: 15 | N9: 15 | O9: 20
A10: 3. INFORMACIÓN DEL CONTRATO
A11: NUMERO SAP | D11: FECHA INICIO | G11: FECHA FINAL
A12: VALOR COP | D12: VALOR USD | G12: VALOR EUR
A13: OBJETO
A15: Prestación de Servicios con HSE | L15: BUENA | M15: 25 | N15: 45 | O15: 30
L16: CONDICIONADA | M16: 15 | N16: 15 | O16: 20
A17: 4. EVALUACIÓN DEL DESEMPEÑO
A18: CRITERIO A CUMPLIR | C18: DESCRIPCIÓN | G18: EVALUADOR | H18: CALIFICACIÓN (Puntos) | I18: DESEMPEÑO
A19: Calidad | B19: Calidad de los Servicios Prestados: cumplimiento de especificaciones | C19: El servicio prestado cumplió con todas las especificaciones y normas técnicas establecidas en el contrato, cumplen satisfactoriamente con los informes periodicos y/o final muestran ampliamente la calidad solicitada. | G19: ADMINISTRADOR DEL CONTRATO / RESPONSABLE TECNICO | I19: =+Datos!G27 -> 10
C20: El servicio prestado tuvo algunos incumplimientos y/o fallas menores, se presentaron falencias menores, de fácil corrección, los informes periodicos y/o final muestran razonablemente el nivel de calidad solicitado.
C21: El servicio prestado tuvo incumplimientos y/o fallas graves, asociadas al cumplimiento de las especificaciones y/o a las normas técnicas, los informes periodicos y/o final cumplen con lo mínimo, pero es susceptible de ser mejorado.
B22: Calidad de los Servicios Prestados: Personal que ejecutó el Servicio. | C22: El personal asignado fue suficiente y tenía las competencias necesarias para ejecutar todas las actividades del contrato. | G22: ADMINISTRADOR DEL CONTRATO / RESPONSABLE TECNICO | I22: =+Datos!G28 -> 10
C23: El personal asignado inicialmente, no fue suficiente y/o no tenía las competencias necesarias para ejecutar todas las actividades del contrato, situación que fue subsanada oportunamente.
C24: El personal asignado no fue suficiente y/o no tenía las competencias necesarias para ejecutar todas las actividades del contrato, situación que no fue subsanada.
B25: Calidad de los servicios prestados: atención a los requerimientos | C25: Cuando fue requerido, el contratista dispuso de personal para atender la situación en el sitio requerido | G25: ADMINISTRADOR DEL CONTRATO / RESPONSABLE TECNICO | I25: =+Datos!G29 -> 10
C26: En algunas de las ocasiones en las que fue requerido, el contratista dispuso de personal para atender la situación en el sitio requerido
C27: Cuando fue requerido, el contratista no dispuso de personal para atender la situación en el sitio requerido
A28: Oportunidad | B28: Oportunidad: cumplimiento de los plazos | C28: El servicio fue entregado en la fecha programada con el proveedor. | G28: ADMINISTRADOR DEL CONTRATO / RESPONSABLE TECNICO | I28: =+Datos!G30 -> 30
C29: El servicio NO fue entregado en la fecha programada con el proveedor, pero NO se generaron impactos negativos para ISA.
C30: El servicio NO fue entregado en la fecha programada con el proveedor y como consecuencia se generaron impactos negativos para ISA.
A31: HSE | B31: Requisitos en Salud Ocupacional. | C31: El contratista cumple con todas las medidas de control (Requisitos legales, Normas, Procedimientos de trabajo, Capacitacion, Matriz de Peligros y Riesgos) durante la ejecución de las actividades objeto del contrato. | G31: ADMINISTRADOR DEL CONTRATO / RESPONSABLE TECNICO | I31: =+Datos!G31 -> 10
C32: El contratista presento algunos incumplimientos de las medidas de control (Requisitos legales, Normas, Procedimientos de trabajo, Capacitacion, Matriz de Peligros y Riesgos) durante la ejecución de las actividades objeto del contrato.
C33: El contratista presento incumplimientos de las medidas de control durante la ejecución de las actividades objeto del contrato (Requisitos legales, Normas, Procedimientos de trabajo, Capacitacion, Matriz de Peligros y Riesgos), o se presentaron accidentes graves o mortales derivados de una deficiente administracion y gestion de los riesgos.
B34: Requisitos Ambientales. | C34: El contratista cumple con todos los Requisitos legales, Normas, Procedimientos, Capacitacion, Matriz de Aspectos e impactos, Plan de Manejo Ambiental durante la ejecucion del contrato. | G34: ADMINISTRADOR DEL CONTRATO / RESPONSABLE TECNICO | I34: =+Datos!G32 -> 10
C35: El contratista presento incumplimientos de los Requisitos legales, Normas, Procedimientos, Capacitacion, Matriz de Aspectos e impactos, Plan de Manejo Ambiental, durante la ejecucion del contrato. Corrigio y gestiono adecuadamente y oportunamente los Impactos Ambientales
C36: El contratista presento incumplimientos de los Requisitos legales, Normas, Procedimientos, Capacitacion, Matriz de Aspectos e impactos, Plan de Manejo Ambiental, durante la ejecucion del contrato. Generando impactos ambientales significativos y consecuencias para ISA como multas, sanciones, afectación de reputación, entre otras.
A37: Gestión | B37: Entrega de Documentos para Orden de Inicio. | C37: El tiempo de entrega a ISA de las Pólizas y demás documentos para dar la Orden de Inicio, fue menor o igual al tiempo establecido en el DSO. | G37: COMPRADOR | I37: =+Datos!G33 -> 10
C38: El tiempo de entrega a ISA de las Pólizas y demás documentos para dar la Orden de Inicio, fue mayor al tiempo establecido en el DSO.
B39: Entrega de Documentos Contractuales. | C39: Todas las facturas y sus soportes, la documentación contractual requerida durante la ejecución (informes, certificados, constancias, licencias, etc) y la documentación postcontractual (manuales, protocolos de pruebas, información técnica, etc) fueron entregadas de acuerdo a lo programado y sin errores. | G39: ADMINISTRADOR DEL CONTRATO / RESPONSABLE ADMINISTRATIVO | I39: =+Datos!G34 -> 10
C40: Algunas facturas y sus soportes, la documentación contractual requerida durante la ejecución (informes, certificados, constancias, licencias, etc) y/o la documentación postcontractual (manuales, protocolos de pruebas, información técnica, etc) fueron entregadas de acuerdo a lo programado pero con errores y como consecuencia se realizó su corrección.
C41: Algunas facturas y sus soportes, la documentación contractual requerida durante la ejecución (informes, certificados, constancias, licencias, etc) y/o la documentación postcontractual (manuales, protocolos de pruebas, información técnica, etc) NO fueron entregadas de acuerdo con lo programado y con errores.
A42: Código de ética / antifraude | B42: Código de ética / antifraCódigo de ética / antifraudeude | C42: El contratista incurrió en faltas al código de ética / antifraude | G42: COMPRADOR / ADMINISTRADOR DEL CONTRATO/RESPONSABLE TÉCNICO / RESPONSABLE ADMINISTRATIVO
...

Sheet Hoja2
A1: NUMCATCORP | B1: DESCRIPCIÓN CATEGORÍA CORPORATIVA | C1: CODCAT_DESCAT | D1: CÓDIGO SUBCATEGORÍA | E1: DESCRIPCIÓN SUBCATEGORÍA | F1: CODSUB_DESCRISUB
A2: 01 | B2: ACTIVIDADES RUTINARIAS MENORES | C2: =A2&"_"&B2 -> 01_ACTIVIDADES RUTINARIAS MENORES | D2: 402010001 | E2: BACHEO MANTENIMIENTO RUTINARIO | F2: =D2&"_"&E2 -> 402010001_BACHEO MANTENIMIENTO RUTINARIO
A3: 01 | B3: ACTIVIDADES RUTINARIAS MENORES | C3: =A3&"_"&B3 -> 01_ACTIVIDADES RUTINARIAS MENORES | D3: 402010002 | E3: BARRERAS NEW JERSEY | F3: =D3&"_"&E3 -> 402010002_BARRERAS NEW JERSEY
A4: 01 | B4: ACTIVIDADES RUTINARIAS MENORES | C4: =A4&"_"&B4 -> 01_ACTIVIDADES RUTINARIAS MENORES | D4: 402010003 | E4: CERCOS METÁLICOS Y MALLAS CIERRO | F4: =D4&"_"&E4 -> 402010003_CERCOS METÁLICOS Y MALLAS CIERRO
A5: 01 | B5: ACTIVIDADES RUTINARIAS MENORES | C5: =A5&"_"&B5 -> 01_ACTIVIDADES RUTINARIAS MENORES | D5: 402010004 | E5: CONTROL HIELOS PAVIMENTO | F5: =D5&"_"&E5 -> 402010004_CONTROL HIELOS PAVIMENTO
A6: 01 | B6: ACTIVIDADES RUTINARIAS MENORES | C6: =A6&"_"&B6 -> 01_ACTIVIDADES RUTINARIAS MENORES | D6: 402010006 | E6: EVENTOS SEGURIDAD VIAL | F6: =D6&"_"&E6 -> 402010006_EVENTOS SEGURIDAD VIAL
A7: 01 | B7: ACTIVIDADES RUTINARIAS MENORES | C7: =A7&"_"&B7 -> 01_ACTIVIDADES RUTINARIAS MENORES | D7: 402010007 | E7: MANTENIMIENTO PANTALLAS ACÚSTICAS | F7: =D7&"_"&E7 -> 402010007_MANTENIMIENTO PANTALLAS ACÚSTICAS
A8: 01 | B8: ACTIVIDADES RUTINARIAS MENORES | C8: =A8&"_"&B8 -> 01_ACTIVIDADES RUTINARIAS MENORES | D8: 402010009 | E8: MANTENIMIENTO PARADEROS DE BUSES | F8: =D8&"_"&E8 -> 402010009_MANTENIMIENTO PARADEROS DE BUSES
A9: 01 | B9: ACTIVIDADES RUTINARIAS MENORES | C9: =A9&"_"&B9 -> 01_ACTIVIDADES RUTINARIAS MENORES | D9: 402010010 | E9: MANTENIMIENTO PLAZAS DE PEAJE | F9: =D9&"_"&E9 -> 402010010_MANTENIMIENTO PLAZAS DE PEAJE
A10: 01 | B10: ACTIVIDADES RUTINARIAS MENORES | C10: =A10&"_"&B10 -> 01_ACTIVIDADES RUTINARIAS MENORES | D10: 402010011 | E10: MANTENIMIENTO RUTINARIO DE BERMAS | F10: =D10&"_"&E10 -> 402010011_MANTENIMIENTO RUTINARIO DE BERMAS
A11: 01 | B11: ACTIVIDADES RUTINARIAS MENORES | C11: =A11&"_"&B11 -> 01_ACTIVIDADES RUTINARIAS MENORES | D11: 402010012 | E11: MANTENIMIENTO RUTINARIO PAVIMENTOS | F11: =D11&"_"&E11 -> 402010012_MANTENIMIENTO RUTINARIO PAVIMENTOS
A12: 01 | B12: ACTIVIDADES RUTINARIAS MENORES | C12: =A12&"_"&B12 -> 01_ACTIVIDADES RUTINARIAS MENORES | D12: 402010013 | E12: MANTENIMIENTO RUTINARIO SEÑALES | F12: =D12&"_"&E12 -> 402010013_MANTENIMIENTO RUTINARIO SEÑALES
A13: 01 | B13: ACTIVIDADES RUTINARIAS MENORES | C13: =A13&"_"&B13 -> 01_ACTIVIDADES RUTINARIAS MENORES | D13: 402010014 | E13: REPOSICIÓN DE PARADEROS DE BUSES | F13: =D13&"_"&E13 -> 402010014_REPOSICIÓN DE PARADEROS DE BUSES
... A80: 09 | B80: MANTENIMIENTO E INSUMOS EQUIPOS TÚNEL Y EQUIPOS DE EMERGENCIA | C80: =A80&"_"&B80 -> 09_MANTENIMIENTO E INSUMOS EQUIPOS TÚNEL Y EQUIPOS DE EMERGENCIA | D80: 402090012 | E80: RECAMBIO VENTILADORES TÚNEL | F80: =D80&"_"&E80 -> 402090012_RECAMBIO VENTILADORES TÚNEL
A81: 10 | B81: MANTENIMIENTO E INSUMOS SISTEMA DE PEAJES Y OTROS EQUIPOS | C81: =A81&"_"&B81 -> 10_MANTENIMIENTO E INSUMOS SISTEMA DE PEAJES Y OTROS EQUIPOS | D81: 402100002 | E81: IMPRESIÓN BOLETOS DE PEAJES | F81: =D81&"_"&E81 -> 402100002_IMPRESIÓN BOLETOS DE PEAJES
A82: 10 | B82: MANTENIMIENTO E INSUMOS SISTEMA DE PEAJES Y OTROS EQUIPOS | C82: =A82&"_"&B82 -> 10_MANTENIMIENTO E INSUMOS SISTEMA DE PEAJES Y OTROS EQUIPOS | D82: 402100003 | E82: INSUMOS MANTENIMIENTO Y REPARACIÓN DE POSTES SOS | F82: =D82&"_"&E82 -> 402100003_INSUMOS MANTENIMIENTO Y REPARACIÓN DE POSTES SOS
A83: 10 | B83: MANTENIMIENTO E INSUMOS SISTEMA DE PEAJES Y OTROS EQUIPOS | C83: =A83&"_"&B83 -> 10_MANTENIMIENTO E INSUMOS SISTEMA DE PEAJES Y OTROS EQUIPOS | D83: 402100004 | E83: MANTENIMIENTO DE PANELES DE MENSAJERÍA VARIABLE | F83: =D83&"_"&E83 -> 402100004_MANTENIMIENTO DE PANELES DE MENSAJERÍA VARIABLE
A84: 10 | B84: MANTENIMIENTO E INSUMOS SISTEMA DE PEAJES Y OTROS EQUIPOS | C84: =A84&"_"&B84 -> 10_MANTENIMIENTO E INSUMOS SISTEMA DE PEAJES Y OTROS EQUIPOS | D84: 402100006 | E84: MANTENIMIENTO EQUIPOS Y TECNOLOGÍAS DE RUTA | F84: =D84&"_"&E84 -> 402100006_MANTENIMIENTO EQUIPOS Y TECNOLOGÍAS DE RUTA
A85: 10 | B85: MANTENIMIENTO E INSUMOS SISTEMA DE PEAJES Y OTROS EQUIPOS | C85: =A85&"_"&B85 -> 10_MANTENIMIENTO E INSUMOS SISTEMA DE PEAJES Y OTROS EQUIPOS | D85: 402100007 | E85: MANTENIMIENTO RUTINARIO DE POSTES SOS | F85: =D85&"_"&E85 -> 402100007_MANTENIMIENTO RUTINARIO DE POSTES SOS
A86: 10 | B86: MANTENIMIENTO E INSUMOS SISTEMA DE PEAJES Y OTROS EQUIPOS | C86: =A86&"_"&B86 -> 10_MANTENIMIENTO E INSUMOS SISTEMA DE PEAJES Y OTROS EQUIPOS | D86: 402100008 | E86: MANTENIMIENTO RUTINARIO DE SISTEMAS DE CCTV | F86: =D86&"_"&E86 -> 402100008_MANTENIMIENTO RUTINARIO DE SISTEMAS DE CCTV
A87: 10 | B87: MANTENIMIENTO E INSUMOS SISTEMA DE PEAJES Y OTROS EQUIPOS | C87: =A87&"_"&B87 -> 10_MANTENIMIENTO E INSUMOS SISTEMA DE PEAJES Y OTROS EQUIPOS | D87: 402100009 | E87: MANTENIMIENTO RUTINARIO DE SISTEMAS DE PEAJES | F87: =D87&"_"&E87 -> 402100009_MANTENIMIENTO RUTINARIO DE SISTEMAS DE PEAJES
A88: 10 | B88: MANTENIMIENTO E INSUMOS SISTEMA DE PEAJES Y OTROS EQUIPOS | C88: =A88&"_"&B88 -> 10_MANTENIMIENTO E INSUMOS SISTEMA DE PEAJES Y OTROS EQUIPOS | D88: 402100011 | E88: RECAMBIO MAYOR PANELES DE MENSAJERÍA VARIABLE | F88: =D88&"_"&E88 -> 402100011_RECAMBIO MAYOR PANELES DE MENSAJERÍA VARIABLE
A89: 10 | B89: MANTENIMIENTO E INSUMOS SISTEMA DE PEAJES Y OTROS EQUIPOS | C89: =A89&"_"&B89 -> 10_MANTENIMIENTO E INSUMOS SISTEMA DE PEAJES Y OTROS EQUIPOS | D89: 402100014 | E89: RECAMBIO MAYOR VÍAS SISTEMAS DE PEAJE | F89: =D89&"_"&E89 -> 402100014_RECAMBIO MAYOR VÍAS SISTEMAS DE PEAJE
A90: 10 | B90: MANTENIMIENTO E INSUMOS SISTEMA DE PEAJES Y OTROS EQUIPOS | C90: =A90&"_"&B90 -> 10_MANTENIMIENTO E INSUMOS SISTEMA DE PEAJES Y OTROS EQUIPOS | D90: 402100015 | E90: RECAMBIO SERVIDORES SISTEMAS DE PEAJE | F90: =D90&"_"&E90 -> 402100015_RECAMBIO SERVIDORES SISTEMAS DE PEAJE
A91: 10 | B91: MANTENIMIENTO E INSUMOS SISTEMA DE PEAJES Y OTROS EQUIPOS | C91: =A91&"_"&B91 -> 10_MANTENIMIENTO E INSUMOS SISTEMA DE PEAJES Y OTROS EQUIPOS | D91: 402100016 | E91: RENOVACIÓN TECNOLÓGICA DE SISTEMAS DE PEAJES | F91: =D91&"_"&E91 -> 402100016_RENOVACIÓN TECNOLÓGICA DE SISTEMAS DE PEAJES
A92: 10 | B92: MANTENIMIENTO E INSUMOS SISTEMA DE PEAJES Y OTROS EQUIPOS | C92: =A92&"_"&B92 -> 10_MANTENIMIENTO E INSUMOS SISTEMA DE PEAJES Y OTROS EQUIPOS | D92: 402100017 | E92: REPUESTOS E INSUMOS PARA EQUIPOS DE PEAJES Y TECNOLOGÍAS DE RUTA | F92: =D92&"_"&E92 -> 402100017_REPUESTOS E INSUMOS PARA EQUIPOS DE PEAJES Y TECNOLOGÍAS DE RUTA
A93: 10 | B93: MANTENIMIENTO E INSUMOS SISTEMA DE PEAJES Y OTROS EQUIPOS | C93: =A93&"_"&B93 -> 10_MANTENIMIENTO E INSUMOS SISTEMA DE PEAJES Y OTROS EQUIPOS | D93: 402100018 | E93: SOFTWARE SISTEMAS DE COBRO | F93: =D93&"_"&E93 -> 402100018_SOFTWARE SISTEMAS DE COBRO
... A130: 18 | B130: SERVICIOS DE ATENCIÓN A USUARIOS | C130: =A130&"_"&B130 -> 18_SERVICIOS DE ATENCIÓN A USUARIOS | D130: 402180005 | E130: SERVICIO PATRULLAS, VIGILANCIA E INSPECCIÓN DE TRÁFICO | F130: =D130&"_"&E130 -> 402180005_SERVICIO PATRULLAS, VIGILANCIA E INSPECCIÓN DE TRÁFICO

Sheet Bienes&Servicios
A1: Evaluación Continua de Acreedores | AE1: 01_ACTIVIDADES RUTINARIAS MENORES
AE2: 01_ALQUILER DE MAQUINARIA, EQUIPOS Y HERRAMIENTAS
A3: NOMBRE DEL ACREEDOR | H3: RUT | AE3: 01_ASEO Y CAFETERÍA
A4: NOMBRE DEL CONTACTO | H4: EMAIL | AE4: 01_DEPORTES Y RECREACIÓN
M5: CONDICIONADA | AE5: 01_DESARROLLO DE SOFTWARE
A6: 1. ETAPA DE EVALUACIÓN | I6: 2. FECHA DE EVALUACIÓN | M6: DEFICIENTE | AE6: 01_PUBLICIDAD, MERCADEO Y COMUNICACIONES
A7: CONTRACTUAL | B7: x | E7: FIN DEL CONTRATO | I7: 45320 | AE7: 01_SERVICIOS ADMINISTRATIVOS
M8: BUENA | N8: 25 | O8: 45 | P8: 30 | AE8: 01_SERVICIOS FINANCIEROS
N9: 15 | O9: 15 | P9: 20 | AE9: 01_SERVICIOS PARA LA GESTIÓN AMBIENTAL Y SOCIAL
A10: 3. INFORMACIÓN DEL CONTRATO | AE10: 01_SUMINISTRO SISTEMAS DE CONTENCIÓN VIAL
A11: NUMERO DEL CONTRATO | D11: FECHA INICIO | H11: FECHA TÉRMINO | AE11: 02_ASESORÍAS Y/O CONSULTORÍAS GENERALES
A12: VALOR TOTAL DEL CONTRATO (En la unidad Correspondiente) | D12: Categoría de Compras | E12: Centralizada | F12: Asistida | G12: Descentralizada | H12: N° y Nombre Categoría | L12: =+Lista -> 0 | AE12: 02_ASESORÍAS Y/O CONSULTORÍAS TÉCNICAS EN VÍAS
H13: Subcategoría | AE13: 02_DOTACIÓN
A14: OBJETO Y ALCANCE : | AE14: 02_PARTES Y ACCESORIOS PARA EQUIPOS DE CÓMPUTO, SERVIDORES, REDES, BACKUP Y ALMACENAMIENTO
AE15: 02_SERVICIOS POSTALES Y DE MENSAJERÍA
A16: Suministro de Bienes y Servicios con HSE | M16: BUENA | N16: 25 | O16: 45 | P16: 30 | AE16: 03_AUDITORÍAS
M17: CONDICIONADA | N17: 15 | O17: 15 | P17: 20 | AE17: 03_CONSTRUCCIÓN DE ELEMENTOS DE DRENAJE SUBSUPERFICIAL
A18: 4. EVALUACIÓN DEL DESEMPEÑO | AE18: 03_FORMACIÓN
A19: CRITERIO A CUMPLIR | C19: DESCRIPCIÓN | H19: EVALUADOR | I19: CALIFICACIÓN (Puntos) | J19: DESEMPEÑO | AE19: 03_MANTENIMIENTO DE EQUIPOS GENERALES
A20: Calidad | B20: Calidad de los Bienes Suministrados: cumplimiento especificaciones | C20: Todos los bienes se recibieron a satisfacción y sin problemas de funcionamiento. | H20: ADMINISTRADOR DEL CONTRATO | J20: =+Datos!G3 -> 0 | AE20: 03_MANTENIMIENTO LOCATIVO
C21: Algunos de los bienes recibidos a satisfacción presentaron problemas de funcionamiento después de la entrega, pero fueron intervenidos oportunamente por el contratista. | AE21: 04_CONSTRUCCIÓN, MANTENIMIENTO Y REPARACIÓN DE TALUDES
C22: Algunos de los bienes recibidos a satisfacción presentaron problemas de funcionamiento después de la entrega, pero NO fueron intervenidos oportunamente por el contratista. (y/o se incurran en faltas o incumplimientos asociados a las especificaciones de los bienes que de lugar a la apliación de una multa) | AE22: 04_MATERIALES Y HERRAMIENTAS DE USO GENERAL
B23: Calidad de los Bienes Suministrados: Cooperación | C23: El personal demuestra, sistemática y evidentemente cooperación que asegura el adecuado suministro de los bienes | J23: =+Datos!G4 -> 0 | AE23: 04_SERVICIOS DE GESTIÓN HUMANA
C24: El personal demuestra poca o regular cooperación, lo que dificulta el adecuado suministro de los bienes | AE24: 04_SERVICIOS DE TELECOMUNICACIONES ADMINISTRATIVOS
C25: El personal no demuestra cooperación, incluso cuando se le solicita, lo que dificulta el adecuado suministro de los bienes | AE25: 04_SERVICIOS JURÍDICOS
B26: Calidad de los Servicios Prestados: cumplimiento de especificaciones | C26: El servicio prestado cumplió con todas las especificaciones y normas técnicas establecidas en el contrato. | J26: =+Datos!G5 -> 3 | AE26: 05_GESTIÓN COMERCIAL RECAUDO ELECTRÓNICO Y TAG
C27: El servicio prestado tuvo algunos incumplimientos y/o fallas menores, asociadas al cumplimiento de las especificaciones y/o a las normas técnicas. | AE27: 05_SOLUCIONES DE CIBERSEGURIDAD ESPECÍFICAS
C28: El servicio prestado tuvo incumplimientos y/o fallas graves, asociadas al cumplimiento de las especificaciones y/o a las normas técnicas. (y/o se incurran en faltas o incumplimientos asociados a las especificaciones de los servicios que de lugar a la apliación de una multa) | AE28: 05_SUMINISTROS GENERALES ADMINISTRATIVOS
B29: Calidad de los Servicios Prestados: Personal que ejecutó el Servicio. | C29: El personal asignado fue suficiente y tenía las competencias necesarias para ejecutar todas las actividades del contrato. | J29: =+Datos!G6 -> 0 | AE29: 06_INSTALACIÓN Y REPARACIÓN SISTEMAS DE CONTENCIÓN VIAL
C30: El personal asignado inicialmente, no fue suficiente y/o no tenía las competencias necesarias para ejecutar todas las actividades del contrato, situación que fue subsanada oportunamente. | AE30: 06_SOLUCIONES DE CIBERSEGURIDAD HOMOLOGADAS PARA EL GRUPO
C31: El personal asignado no fue suficiente y/o no tenía las competencias necesarias para ejecutar todas las actividades del contrato, situación que no fue subsanada. (y/o se incurran en faltas o incumplimientos asociados al desempeño del personal que ejecutó el servicio que de lugar a la apliación de una multa) | AE31: 07_MANTENIMIENTO CALLES DE SERVICIO O ACCESOS GRANULARES
B32: Calidad de los servicios prestados: atención a los requerimientos | C32: Cuando fue requerido, el contratista dispuso el personal y / o los medios requeridos para atender la situación en el sitio requerido | J32: =+Datos!G7 -> 3 | M32: Los bienes No fueron entregados en la fecha programada, pero No genero | AE32: 07_SOLUCIONES DE CÓMPUTO PERSONAL
C33: En algunas de las ocasiones en las que fue requerido, el contratista dispuso el personal y / o los medios requeridos para atender la situación en el sitio requerido | AE33: 07_VIGILANCIA
C34: Cuando fue requerido, el contratista no dispuso el personal y / o los medios requeridos para atender la situación en el sitio requerido. (y/o se incurran en faltas o incumplimientos asociados a la atención oportuna de los requerimientos que de lugar a la apliación de una multa) | AE34: 08_MANTENIMIENTO DE PAVIMENTO DE HORMIGÓN
A35: Oportunidad | B35: Oportunidad: cumplimiento de los plazos programados | C35: Los bienes fueron entregados/ los servicios fueron prestados en la fecha programada con el proveedor. | H35: ADMINISTRADOR DEL CONTRATO | J35: =+Datos!G8 -> 30 | AE35: 08_SOLUCIONES DE ERP Y SISTEMAS VINCULADOS
C36: Los bienes NO fueron entregados/ los servicios No fueron prestados en la fecha programada con el proveedor, pero NO se generaron impactos negativos para el Mandante. | AE36: 09_MANTENIMIENTO E INSUMOS EQUIPOS TÚNEL Y EQUIPOS DE EMERGENCIA
C37: Los bienes NO fueron entregados/ los servicios No fueron prestados en la fecha programada con el proveedor y como consecuencia se generaron impactos negativos para Iel Mandante. (y/o se incurran en faltas o incumplimientos asociados a los plazos programados de los bienes que de lugar a la apliación de una multa) | AE37: 09_SOLUCIONES DE SERVIDORES, BACKUP Y ALMACENAMIENTO
A38: Prevención de Riesgos y Medioambiente | B38: Requisitos en Salud Ocupacional. | C38: El contratista durante la ejecución del contrato cumplió con los temas administrativos y de terreno de Seguridad y Salud en el Trabajo (carpetas de arranque, procedimientos, MIPER, entrega de información, respuesta de inspecciones en terreno, etc.) en acuerdo a todas las actividades del objeto del contrato y el reglamento especial de empresas contratistas vigente. Nota: Si por cualquier causa o motivo se presenta algún accidente grave o mortal aunque el contratista haya cumplido a cavalidad lo antes mencionado su nota total será 0. | H38: ADMINISTRADOR DEL CONTRATO / JEFE PREVENCIÓN DE RIESGOS | J38: =+Datos!G9 -> 5 | AE38: 10_MANTENIMIENTO E INSUMOS SISTEMA DE PEAJES Y OTROS EQUIPOS
C39: El contratista durante la ejecución del contrato presento algunos incumplimientos con los temas administrativos y de terreno de Seguridad y Salud en el Trabajo (carpetas de arranque, procedimientos, MIPER, entrega de información, respuesta de inspecciones etc.) en acuerdo a todas las actividades del objeto del contrato y el reglamento especial de empresas contratistas vigente. | AE39: 10_SOLUCIONES DE TELEFONÍA MÓVIL
C40: El contratista durante la ejecución del contrato presento incumplimientos reiterativos con temas administrativos y de terreno de Seguridad y Salud en el Trabajo (carpetas de arranque, procedimientos, MIPER, entrega de información, respuesta de inspecciones etc.), o se presentaron accidentes graves o mortales derivados de una deficiente administracion y gestion de los riesgos, y/o se incurrieron en faltas o incumplimientos asociados a medidas de control, procedimientos de trabajos, capacitación, normas y todo lo inherente a la seguridad y salud en el trabajo que de lugar a la apliación de una multa en acuerdo a todas las actividades del objeto del contrato y el reglamento especial de empresas contratistas vigente. | AE40: 11_MANTENIMIENTO MAYOR EN ESTRUCTURAS Y CAUCES
...

Sheet Hoja1
A1: Categorías | C1: 01_ACTIVIDADES RUTINARIAS MENORES | D1: 01_ALQUILER DE MAQUINARIA, EQUIPOS Y HERRAMIENTAS | E1: 01_ASEO Y CAFETERÍA | F1: 01_DEPORTES Y RECREACIÓN | G1: 01_DESARROLLO DE SOFTWARE | H1: 01_PUBLICIDAD, MERCADEO Y COMUNICACIONES | I1: 01_SERVICIOS ADMINISTRATIVOS | J1: 01_SERVICIOS FINANCIEROS | K1: 01_SERVICIOS PARA LA GESTIÓN AMBIENTAL Y SOCIAL | L1: 01_SUMINISTRO SISTEMAS DE CONTENCIÓN VIAL | M1: 02_ASESORÍAS Y/O CONSULTORÍAS GENERALES | N1: 02_ASESORÍAS Y/O CONSULTORÍAS TÉCNICAS EN VÍAS | O1: 02_DOTACIÓN | P1: 02_PARTES Y ACCESORIOS PARA EQUIPOS DE CÓMPUTO, SERVIDORES, REDES, BACKUP Y ALMACENAMIENTO | Q1: 02_SERVICIOS POSTALES Y DE MENSAJERÍA | R1: 03_AUDITORÍAS | S1: 03_CONSTRUCCIÓN DE ELEMENTOS DE DRENAJE SUBSUPERFICIAL | T1: 03_FORMACIÓN | U1: 03_MANTENIMIENTO DE EQUIPOS GENERALES | V1: 03_MANTENIMIENTO LOCATIVO | W1: 04_CONSTRUCCIÓN, MANTENIMIENTO Y REPARACIÓN DE TALUDES | X1: 04_MATERIALES Y HERRAMIENTAS DE USO GENERAL | Y1: 04_SERVICIOS DE GESTIÓN HUMANA | Z1: 04_SERVICIOS DE TELECOMUNICACIONES ADMINISTRATIVOS | AA1: 04_SERVICIOS JURÍDICOS | AB1: 05_GESTIÓN COMERCIAL RECAUDO ELECTRÓNICO Y TAG | AC1: 05_SOLUCIONES DE CIBERSEGURIDAD ESPECÍFICAS | AD1: 05_SUMINISTROS GENERALES ADMINISTRATIVOS | AE1: 06_INSTALACIÓN Y REPARACIÓN SISTEMAS DE CONTENCIÓN VIAL | AF1: 06_SOLUCIONES DE CIBERSEGURIDAD HOMOLOGADAS PARA EL GRUPO | AG1: 07_MANTENIMIENTO CALLES DE SERVICIO O ACCESOS GRANULARES | AH1: 07_SOLUCIONES DE CÓMPUTO PERSONAL | AI1: 07_VIGILANCIA | AJ1: 08_MANTENIMIENTO DE PAVIMENTO DE HORMIGÓN | AK1: 08_SOLUCIONES DE ERP Y SISTEMAS VINCULADOS | AL1: 09_MANTENIMIENTO E INSUMOS EQUIPOS TÚNEL Y EQUIPOS DE EMERGENCIA | AM1: 09_SOLUCIONES DE SERVIDORES, BACKUP Y ALMACENAMIENTO | AN1: 10_MANTENIMIENTO E INSUMOS SISTEMA DE PEAJES Y OTROS EQUIPOS | AO1: 10_SOLUCIONES DE TELEFONÍA MÓVIL | AP1: 11_MANTENIMIENTO MAYOR EN ESTRUCTURAS Y CAUCES | AQ1: 11_SOLUCIONES SOFTWARE COMERCIALES (NO VINCULADAS A ERP NI A PLATAFORMA BASE Y DE PRODUCTIVIDAD) | AR1: 12_MANTENIMIENTO PAVIMENTOS Y BERMAS DE ASFALTO | AS1: 12_SOLUCIONES TECNOLÓGICAS ESTÁNDAR DE PLATAFORMA BASE Y DE PRODUCTIVIDAD | AT1: 13_MANTENIMIENTO Y REPOSICIÓN DE SEÑALIZACIÓN HORIZONTAL Y VERTICAL | AU1: 13_SOPORTE Y MANTENIMIENTO DE INFRAESTRUCTURA TECNOLÓGICA | AV1: 14_PAISAJISMO, MANTENIMIENTO FAJA Y MANTENIMIENTO DE ELEMENTOS DE DRENAJE SUPERFICIAL | AW1: 14_SOPORTE Y MANTENIMIENTO DE SOLUCIONES TECNOLÓGICAS NO VINCULADAS AL ERP | AX1: 15_SELLOS DE JUNTAS Y GRIETAS DE PAVIMENTOS | AY1: 15_SOPORTE Y MANTENIMIENTO ERP Y SOLUCIONES TECNOLÓGICAS VINCULADAS DEL MISMO FABRICANTE | AZ1: 16_SERVICIO DE PEAJISTAS Y TRANSPORTE DE DINERO | BA1: 17_SERVICIO DE PESAJE Y CONTEO DE TRÁFICO | BB1: 18_SERVICIOS DE ATENCIÓN A USUARIOS
A2: 01_ACTIVIDADES RUTINARIAS MENORES | C2: 402010001_BACHEO MANTENIMIENTO RUTINARIO | D2: 101010006_ALQUILER DE VEHÍCULOS | E2: 103010001_ASEO Y CAFETERÍA | F2: 111010003_SERVICIOS DE RECREACIÓN Y DEPORTE | G2: 112010001_DESARROLLO DE SOFTWARE | H2: 106010002_AVISOS Y PUBLICACIONES | I2: 108010001_ADMINISTRACIÓN DOCUMENTAL | J2: 109010003_ASESORÍAS Y/O CONSULTORÍAS EN SERVICIOS FINANCIEROS | K2: 113010001_ELABORACIÓN DE ESTUDIOS AMBIENTALES | L2: 401010001_SUMINISTRO SISTEMAS DE CONTENCIÓN VIAL | M2: 110020006_ASESORÍAS Y/O CONSULTORÍAS EN TECNOLOGÍA COMUNES O ESPECIALIZADAS | N2: 402020001_ESTUDIOS Y PROYECTOS VIALES | O2: 111020001_UNIFORMES DE DOTACIÓN | P2: 112020001_PARTES Y ACCESORIOS PARA EQUIPOS DE CÓMPUTO, SERVIDORES, REDES, BACKUP Y ALMACENAMIENTO | Q2: 108020003_SERVICIO DE MENSAJERÍA | R2: 110030004_AUDITORÍAS INTERNAS | S2: 402030001_DRENES Y SUBDRENES | T2: 111030001_ELABORACIÓN DE CURSOS VIRTUALES | U2: 101030005_MANTENIMIENTO EQUIPOS PARA USO EN INFRAESTRUCTURA Y ZONAS COMUNES | V2: 103030005_MANTENIMIENTO ELÉCTRICO | W2: 402040001_CONTENCIÓN TALUDES | X2: 101040004_COMBUSTIBLES | Y2: 111040007_MEDICIONES DE GESTIÓN HUMANA | Z2: 112040001_SERVICIOS DE TELECOMUNICACIONES ADMINISTRATIVOS | AA2: 110040001_ASESORÍA JURÍDICA Y REGULATORIA | AB2: 402050001_COBRANZA MEDIOS DE PAGO ELECTRÓNICOS | AC2: 112050001_SOLUCIONES DE CIBERSEGURIDAD ESPECÍFICAS | AD2: 101050001_AGUA POTABLE PARA SEDES Y SUBESTACIONES | AE2: 402060001_INSTALACIÓN Y REPARACIÓN SISTEMAS DE CONTENCIÓN VIAL | AF2: 112060001_SOLUCIONES DE CIBERSEGURIDAD HOMOLOGADAS PARA EL GRUPO | AG2: 402070001_MANTENIMIENTO CALLES DE SERVICIO O ACCESOS GRANULARES | AH2: 112070001_SOLUCIONES DE CÓMPUTO PERSONAL | AI2: 103070002_SERVICIO DE VIGILANCIA Y SEGURIDAD | AJ2: 402080001_CEPILLADO PAVIMENTOS | AK2: 112080001_SOLUCIONES DE ERP Y SISTEMAS VINCULADOS | AL2: 402090001_ACTUALIZACIÓN SOFTWARE TÚNEL | AM2: 112090001_SOLUCIONES DE SERVIDORES, BACKUP Y ALMACENAMIENTO | AN2: 402100002_IMPRESIÓN BOLETOS DE PEAJES | AO2: 112100001_SOLUCIONES DE TELEFONÍA MÓVIL | AP2: 402110001_DRENAJE PUENTES | AQ2: 112110002_SOLUCIONES DE SOFTWARE GENÉRICO | AR2: 402120001_BACHEO MANTENIMIENTO MAYOR | AS2: 112120001_SOLUCIONES TECNOLÓGICAS ESTÁNDAR DE PLATAFORMA BASE Y DE PRODUCTIVIDAD | AT2: 402130001_DEMARCACIÓN PAVIMENTO | AU2: 112130001_SOPORTE Y MANTENIMIENTO DE INFRAESTRUCTURA TECNOLÓGICA | AV2: 402140001_ELEMENTOS DE DRENAJE | AW2: 112140001_SOPORTE Y MANTENIMIENTO DE SOLUCIONES TECNOLÓGICAS NO VINCULADAS AL ERP | AX2: 402150001_SELLO DE JUNTAS Y GRIETAS | AY2: 112150001_SOPORTE Y MANTENIMIENTO ERP Y SOLUCIONES TECNOLÓGICAS VINCULADAS DEL MISMO FABRICANTE | AZ2: 402160001_SERVICIO TRANSPORTE DE DINERO | BA2: 402170002_SERVICIO CONTEO DE TRÁFICO | BB2: 402180001_SERVICIO CHOFER PARAMÉDICOS
A3: 01_ALQUILER DE MAQUINARIA, EQUIPOS Y HERRAMIENTAS | C3: 402010002_BARRERAS NEW JERSEY | E3: 103010003_SERVICIO DE ALIMENTACIÓN | H3: 106010004_DISEÑO E IMPRESIÓN DIGITAL | I3: 108010008_SERVICIOS DE IMPRESIÓN Y REPROGRAFÍA | J3: 109010007_SERVICIO DE ASEGURAMIENTO | M3: 110020007_ASESORÍAS Y/O CONSULTORÍAS ESTRATÉGICAS | T3: 111030002_EVENTOS DE FORMACIÓN | U3: 101030009_MANTENIMIENTO VEHÍCULOS | V3: 103030006_MANTENIMIENTO LOCATIVO GENERAL (TECHOS, PAREDES, PINTURA, JARDINES, ETC) | AA3: 110040005_SERVICIOS NOTARIALES | AB3: 402050002_OFICINAS COMERCIALES | AD3: 101050007_ÚTILES DE ESCRITORIO Y PAPELERÍA | AJ3: 402080002_ESTABILIZACIÓN LOSAS | AL3: 402090002_MANTENIMIENTO EQUIPOS DE EMERGENCIA | AN3: 402100003_INSUMOS MANTENIMIENTO Y REPARACIÓN DE POSTES SOS | AP3: 402110002_JUNTAS EXPANSIÓN | AR3: 402120002_FRESADO Y MICROFRESADO CARPETA ASFÁLTICA | AT3: 402130002_REMOCIÓN E INSTALACIÓN DE SEÑALES | AV3: 402140002_LIMPIEZA Y ROCE | AZ3: 402160002_SERVICIOS DE PEAJISTAS | BA3: 402170003_SERVICIO DE PESAJE | BB3: 402180002_SERVICIO AMBULANCIA
A4: 01_ASEO Y CAFETERÍA | C4: 402010003_CERCOS METÁLICOS Y MALLAS CIERRO | H4: 106010005_DISEÑO Y GESTIÓN DE ESTRATEGIAS DE COMUNICACIÓN | J4: 109010008_SERVICIO DE INTERMEDIACIÓN DE SEGUROS | AB4: 402050004_SERVICIO MEDIOS DE PAGO ELECTRÓNICOS | AJ4: 402080003_REEMPLAZO DE LOSAS DE HORMIGÓN RÍGIDO | AL4: 402090003_MANTENIMIENTO SISTEMAS DE EQUIPOS CONTROL | AN4: 402100004_MANTENIMIENTO DE PANELES DE MENSAJERÍA VARIABLE | AP4: 402110003_MANTENIMIENTO BARANDAS | AR4: 402120003_MANTENIMIENTO CARPETA RODADURA | AT4: 402130003_TACHAS Y TACHONES REFLECTANTES | AV4: 402140003_PAISAJISMO | BB4: 402180004_SERVICIO GRÚAS
A5: 01_DEPORTES Y RECREACIÓN | C5: 402010004_CONTROL HIELOS PAVIMENTO | H5: 106010007_ELABORACIÓN DE PIEZAS COMUNICACIONALES | AJ5: 402080004_REPARACIÓN DE ESPESOR PARCIAL O RODADURA | AL5: 402090004_MANTENIMIENTO SISTEMAS DE EQUIPOS ELÉCTRICOS | AN5: 402100006_MANTENIMIENTO EQUIPOS Y TECNOLOGÍAS DE RUTA | AP5: 402110004_MANTENIMIENTO CAUCES | AR5: 402120004_MANTENIMIENTO MAYOR BERMAS | AV5: 402140004_RETIRO BASURA Y ESCOMBROS | BB5: 402180005_SERVICIO PATRULLAS, VIGILANCIA E INSPECCIÓN DE TRÁFICO
A6: 01_DESARROLLO DE SOFTWARE | C6: 402010006_EVENTOS SEGURIDAD VIAL | H6: 106010008_ENCUESTAS | AL6: 402090005_MANTENIMIENTO SISTEMAS DE VENTILADORES | AN6: 402100007_MANTENIMIENTO RUTINARIO DE POSTES SOS | AP6: 402110005_MANTENIMIENTO PAVIMENTOS PUENTES Y ESTRUCTURAS | AR6: 402120005_MANTENIMIENTO MAYOR CALLES DE SERVICIO O ACCESOS | AV6: 402140005_SANEAMIENTO
A7: 01_PUBLICIDAD, MERCADEO Y COMUNICACIONES | C7: 402010007_MANTENIMIENTO PANTALLAS ACÚSTICAS | AL7: 402090006_RECAMBIO EQUIPOS DE CONTROL E INFORMACIÓN TÚNEL | AN7: 402100008_MANTENIMIENTO RUTINARIO DE SISTEMAS DE CCTV | AR7: 402120006_MICROAGLOMERADOS
A8: 01_SERVICIOS ADMINISTRATIVOS | C8: 402010009_MANTENIMIENTO PARADEROS DE BUSES | AL8: 402090007_RECAMBIO EQUIPOS ELÉCTRICOS TÚNEL | AN8: 402100009_MANTENIMIENTO RUTINARIO DE SISTEMAS DE PEAJES | AR8: 402120007_SUMINISTRO Y COLOCACIÓN MEZCLA ASFÁLTICA CALIENTE
A9: 01_SERVICIOS FINANCIEROS | C9: 402010010_MANTENIMIENTO PLAZAS DE PEAJE | AL9: 402090008_RECAMBIO GENERADOR PLAZAS PEAJE O TÚNEL | AN9: 402100011_RECAMBIO MAYOR PANELES DE MENSAJERÍA VARIABLE
A10: 01_SERVICIOS PARA LA GESTIÓN AMBIENTAL Y SOCIAL | C10: 402010011_MANTENIMIENTO RUTINARIO DE BERMAS | AL10: 402090009_RECAMBIO SERVIDORES SISTEMAS TÚNEL | AN10: 402100014_RECAMBIO MAYOR VÍAS SISTEMAS DE PEAJE
A11: 01_SUMINISTRO SISTEMAS DE CONTENCIÓN VIAL | C11: 402010012_MANTENIMIENTO RUTINARIO PAVIMENTOS | AL11: 402090010_RECAMBIO SISTEMAS ILUMINACIÓN TÚNEL | AN11: 402100015_RECAMBIO SERVIDORES SISTEMAS DE PEAJE
A12: 02_ASESORÍAS Y/O CONSULTORÍAS GENERALES | C12: 402010013_MANTENIMIENTO RUTINARIO SEÑALES | AL12: 402090011_RECAMBIO TABLEROS ELÉCTRICOS TÚNEL | AN12: 402100016_RENOVACIÓN TECNOLÓGICA DE SISTEMAS DE PEAJES
A13: 02_ASESORÍAS Y/O CONSULTORÍAS TÉCNICAS EN VÍAS | C13: 402010014_REPOSICIÓN DE PARADEROS DE BUSES | AL13: 402090012_RECAMBIO VENTILADORES TÚNEL | AN13: 402100017_REPUESTOS E INSUMOS PARA EQUIPOS DE PEAJES Y TECNOLOGÍAS DE RUTA
A14: 02_DOTACIÓN | C14: 402010015_RETIRO Y BORRADO PROPAGANDA | AN14: 402100018_SOFTWARE SISTEMAS DE COBRO
A15: 02_PARTES Y ACCESORIOS PARA EQUIPOS DE CÓMPUTO, SERVIDORES, REDES, BACKUP Y ALMACENAMIENTO | AN15: 402100019_TAG
A16: 02_SERVICIOS POSTALES Y DE MENSAJERÍA | AN16: 402100020_TARJETA SIN CONTACTO
A17: 03_AUDITORÍAS
A18: 03_CONSTRUCCIÓN DE ELEMENTOS DE DRENAJE SUBSUPERFICIAL
A19: 03_FORMACIÓN
A20: 03_MANTENIMIENTO DE EQUIPOS GENERALES
A21: 03_MANTENIMIENTO LOCATIVO
A22: 04_CONSTRUCCIÓN, MANTENIMIENTO Y REPARACIÓN DE TALUDES
A23: 04_MATERIALES Y HERRAMIENTAS DE USO GENERAL
A24: 04_SERVICIOS DE GESTIÓN HUMANA
A25: 04_SERVICIOS DE TELECOMUNICACIONES ADMINISTRATIVOS
A26: 04_SERVICIOS JURÍDICOS
A27: 05_GESTIÓN COMERCIAL RECAUDO ELECTRÓNICO Y TAG
A28: 05_SOLUCIONES DE CIBERSEGURIDAD ESPECÍFICAS
... A53: 18_SERVICIOS DE ATENCIÓN A USUARIOS

Sheet Datos
A1: Bienes y Servicios | C1: Respuesta | D1: Puntos posibles | G1: Calificación
D2: 1 | E2: 2 | F2: 3
A3: Calidad | B3: Calidad de los Bienes Suministrados: cumplimiento especificaciones | C3: 3 | D3: =+'Bienes&Servicios'!$C$54/5 -> 6 | E3: =+D3/2 -> 3 | F3: 0 | G3: =IF(C3=$D$2,D3,IF(C3=$E$2,E3,IF(C3=$F$2,F3))) -> 0
B4: Calidad de los Bienes Suministrados: Cooperación | C4: 3 | D4: =+'Bienes&Servicios'!$C$54/5 -> 6 | E4: =+D4/2 -> 3 | F4: 0 | G4: =IF(C4=$D$2,D4,IF(C4=$E$2,E4,IF(C4=$F$2,F4))) -> 0
B5: Calidad de los Servicios Prestados: cumplimiento de especificaciones | C5: 2 | D5: =+'Bienes&Servicios'!$C$54/5 -> 6 | E5: =+D5/2 -> 3 | F5: 0 | G5: =IF(C5=$D$2,D5,IF(C5=$E$2,E5,IF(C5=$F$2,F5))) -> 3
B6: Calidad de los Servicios Prestados: Personal que ejecutó el Servicio. | C6: 3 | D6: =+'Bienes&Servicios'!$C$54/5 -> 6 | E6: =+D6/2 -> 3 | F6: 0 | G6: =IF(C6=$D$2,D6,IF(C6=$E$2,E6,IF(C6=$F$2,F6))) -> 0
B7: Calidad de los servicios prestados: atención a los requerimientos | C7: 2 | D7: =+'Bienes&Servicios'!$C$54/5 -> 6 | E7: =+D7/2 -> 3 | F7: 0 | G7: =IF(C7=$D$2,D7,IF(C7=$E$2,E7,IF(C7=$F$2,F7))) -> 3
A8: Oportunidad | B8: Oportunidad: cumplimiento de los plazos programados | C8: 1 | D8: =+'Bienes&Servicios'!C55 -> 30 | E8: =+D8/2 -> 15 | F8: 0 | G8: =IF(C8=$D$2,D8,IF(C8=$E$2,E8,IF(C8=$F$2,F8))) -> 30
A9: HSE | B9: Requisitos en Salud Ocupacional. | C9: 2 | D9: =+'Bienes&Servicios'!$C$56/2 -> 10 | E9: =+D9/2 -> 5 | F9: 0 | G9: =IF(C9=$D$2,D9,IF(C9=$E$2,E9,IF(C9=$F$2,F9))) -> 5
B10: Requisitos Ambientales. | C10: 1 | D10: =+'Bienes&Servicios'!$C$56/2 -> 10 | E10: =+D10/2 -> 5 | F10: 0 | G10: =IF(C10=$D$2,D10,IF(C10=$E$2,E10,IF(C10=$F$2,F10))) -> 10
A11: Gestión | B11: Entrega de Documentos para Orden de Inicio. | C11: 1 | D11: =+'Bienes&Servicios'!$C$53/2 -> 10 | E11: 0 | F11: 0 | G11: =IF(C11=$D$2,D11,IF(C11=$E$2,E11,IF(C11=$F$2,F11))) -> 10
B12: Entrega de Documentos Contractuales. | C12: 3 | D12: =+'Bienes&Servicios'!$C$53/2 -> 10 | E12: =+D12/2 -> 5 | F12: 0 | G12: =IF(C12=$D$2,D12,IF(C12=$E$2,E12,IF(C12=$F$2,F12))) -> 0
A13: Ética | B13: Código de ética / antifraude | C13: FALSE
A14: Total | G14: =IF(G13=0,0,SUM(G3:G12)) -> 0
A16: ¿HSE? | B16: TRUE
A17: CRITERIO | C17: Con HSE | D17: Sin HSE | E17: Total
C18: Calificación posible | D18: Calificación posible | E18: Calificación obtenida
A19: GESTIÓN | C19: 20 | D19: =+(C19/SUM($C$19:$C$21))*100 -> 25 | E19: =SUM(G11:G12) -> 10
A20: CALIDAD | C20: 30 | D20: =+(C20/SUM($C$19:$C$21))*100 -> 37.5 | E20: =SUM(G3:G7) -> 6
A21: OPORTUNIDAD | C21: 30 | D21: =+(C21/SUM($C$19:$C$21))*100 -> 37.5 | E21: =SUM(G8) -> 30
A22: HSE | C22: 20 | D22: 0 | E22: =SUM(G9:G10) -> 15
A25: Servicios | C25: Respuesta | D25: Puntos posibles | G25: Calificación
D26: 1 | E26: 2 | F26: 3
A27: Calidad | B27: Calidad de los Servicios Prestados: cumplimiento de especificaciones | C27: 1 | D27: =+Servicios!$C$47/3 -> 10 | E27: =+D27/2 -> 5 | F27: 0 | G27: =IF(C27=$D$26,D27,IF(C27=$E$26,E27,IF(C27=$F$26,F27))) -> 10
B28: Calidad de los Servicios Prestados: Personal que ejecutó el Servicio. | C28: 1 | D28: =+Servicios!$C$47/3 -> 10 | E28: =+D28/2 -> 5 | F28: 0 | G28: =IF(C28=$D$26,D28,IF(C28=$E$26,E28,IF(C28=$F$26,F28))) -> 10
B29: Calidad de los servicios prestados: atención a los requerimientos | C29: 1 | D29: =+Servicios!$C$47/3 -> 10 | E29: =+D29/2 -> 5 | F29: 0 | G29: =IF(C29=$D$26,D29,IF(C29=$E$26,E29,IF(C29=$F$26,F29))) -> 10
A30: Oportunidad | B30: Oportunidad: cumplimiento de los plazos | C30: 1 | D30: =+Servicios!C48 -> 30 | E30: =+D30/2 -> 15 | F30: 0 | G30: =IF(C30=$D$26,D30,IF(C30=$E$26,E30,IF(C30=$F$26,F30))) -> 30
A31: HSE | B31: Requisitos en Salud Ocupacional. | C31: 1 | D31: =+Servicios!$C$49/2 -> 10 | E31: =+D31/2 -> 5 | F31: 0 | G31: =IF(C31=$D$26,D31,IF(C31=$E$26,E31,IF(C31=$F$26,F31))) -> 10
B32: Requisitos Ambientales. | C32: 1 | D32: =+Servicios!$C$49/2 -> 10 | E32: =+D32/2 -> 5 | F32: 0 | G32: =IF(C32=$D$26,D32,IF(C32=$E$26,E32,IF(C32=$F$26,F32))) -> 10
A33: Gestión | B33: Entrega de Documentos para Orden de Inicio. | C33: 1 | D33: =+Servicios!$C$46/2 -> 10 | E33: 0 | F33: 0 | G33: =IF(C33=$D$26,D33,IF(C33=$E$26,E33,IF(C33=$F$26,F33))) -> 10
B34: Entrega de Documentos Contractuales. | C34: 1 | D34: =+Servicios!$C$46/2 -> 10 | E34: =+D34/2 -> 5 | F34: 0 | G34: =IF(C34=$D$26,D34,IF(C34=$E$26,E34,IF(C34=$F$26,F34))) -> 10
A35: Etica | B35: Código de ética / antifraude | C35: FALSE
A36: Total | G36: =IF(G35=0,0,SUM(G25:G34)) -> 0
A38: ¿HSE? | B38: TRUE
A39: CRITERIO | C39: Con HSE | D39: Sin HSE | E39: Total
C40: Calificación posible | D40: Calificación posible | E40: Calificación obtenida
A41: GESTIÓN | C41: 20 | D41: =+(C41/SUM($C$19:$C$21))*100 -> 25 | E41: =SUM(G33:G34) -> 20
A42: CALIDAD | C42: 30 | D42: =+(C42/SUM($C$19:$C$21))*100 -> 37.5 | E42: =SUM(G27:G29) -> 30
A43: OPORTUNIDAD | C43: 30 | D43: =+(C43/SUM($C$19:$C$21))*100 -> 37.5 | E43: =SUM(G30) -> 30
A44: HSE | C44: 20 | D44: 0 | E44: =SUM(G31:G32) -> 20
...
